File: Chapter4_Crystallinity-measurement/data/XRD/heated/HDPE_110C_1.csv
[Measurement conditions]
Sample identification,HDPE_110C_1
Comment,
Anode material,Cu
K-Alpha1 wavelength,1.5405980
K-Alpha2 wavelength,1.5444260
Ratio K-Alpha2/K-Alpha1,0.500
Divergence slit,Fixed,0.76mm
Monochromator used,NO
Generator voltage, 40
Tube current, 15
File date and time,12/Jun/2025 14:48
Unit cell,
h k l, 0 0 0
Scan axis,Gonio
Scan range,10.009000000,40.000374400
Scan step size,0.0651986
No. of points, 460
Scan type,CONTINUOUS
Time per step,71.910
[Scan points]
Angle, TimePerStep, Intensity, ESD
10.041599320, 71.910, 10837.0, 104.1009
10.106797960, 71.910, 10918.0, 104.4892
10.171996600, 71.910, 10953.0, 104.6566
10.237195240, 71.910, 10772.0, 103.7882
10.302393880, 71.910, 10816.0, 104.0000
10.367592520, 71.910, 10928.0, 104.5371
10.432791160, 71.910, 10975.0, 104.7616
10.497989800, 71.910, 10744.0, 103.6533
10.563188440, 71.910, 10827.0, 104.0529
10.628387080, 71.910, 10981.0, 104.7903
10.693585720, 71.910, 10921.0, 104.5036
10.758784360, 71.910, 10926.0, 104.5275
10.823983000, 71.910, 10969.0, 104.7330
10.889181640, 71.910, 10949.0, 104.6375
10.954380280, 71.910, 10956.0, 104.6709
11.019578920, 71.910, 10897.0, 104.3887
11.084777560, 71.910, 11025.0, 105.0000
11.149976200, 71.910, 10789.0, 103.8701
11.215174840, 71.910, 11012.0, 104.9381
11.280373480, 71.910, 11001.0, 104.8857
11.345572120, 71.910, 11073.0, 105.2283
11.410770760, 71.910, 10966.0, 104.7187
11.475969400, 71.910, 11317.0, 106.3814
11.541168040, 71.910, 11252.0, 106.0754
11.606366680, 71.910, 11057.0, 105.1523
11.671565320, 71.910, 10946.0, 104.6231
11.736763960, 71.910, 11162.0, 105.6504
11.801962600, 71.910, 11080.0, 105.2616
11.867161240, 71.910, 10812.0, 103.9808
11.932359880, 71.910, 11122.0, 105.4609
11.997558520, 71.910, 11075.0, 105.2378
12.062757160, 71.910, 11110.0, 105.4040
12.127955800, 71.910, 11303.0, 106.3156
12.193154440, 71.910, 11071.0, 105.2188
12.258353080, 71.910, 11406.0, 106.7989
12.323551720, 71.910, 11403.0, 106.7848
12.388750360, 71.910, 11376.0, 106.6583
12.453949000, 71.910, 11553.0, 107.4849
12.519147640, 71.910, 11421.0, 106.8691
12.584346280, 71.910, 11640.0, 107.8888
12.649544920, 71.910, 11215.0, 105.9009
12.714743560, 71.910, 11707.0, 108.1989
12.779942200, 71.910, 11452.0, 107.0140
12.845140840, 71.910, 11749.0, 108.3928
12.910339480, 71.910, 11644.0, 107.9074
12.975538120, 71.910, 11700.0, 108.1665
13.040736760, 71.910, 11626.0, 107.8239
13.105935400, 71.910, 11874.0, 108.9679
13.171134040, 71.910, 11908.0, 109.1238
13.236332680, 71.910, 11918.0, 109.1696
13.301531320, 71.910, 12109.0, 110.0409
13.366729960, 71.910, 12169.0, 110.3132
13.431928600, 71.910, 12309.0, 110.9459
13.497127240, 71.910, 12491.0, 111.7631
13.562325880, 71.910, 12500.0, 111.8034
13.627524520, 71.910, 12505.0, 111.8258
13.692723160, 71.910, 12698.0, 112.6854
13.757921800, 71.910, 12723.0, 112.7963
13.823120440, 71.910, 12965.0, 113.8640
13.888319080, 71.910, 12934.0, 113.7277
13.953517720, 71.910, 13306.0, 115.3516
14.018716360, 71.910, 13158.0, 114.7083
14.083915000, 71.910, 13161.0, 114.7214
14.149113640, 71.910, 13411.0, 115.8059
14.214312280, 71.910, 13670.0, 116.9188
14.279510920, 71.910, 13833.0, 117.6138
14.344709560, 71.910, 13858.0, 117.7200
14.409908200, 71.910, 13906.0, 117.9237
14.475106840, 71.910, 14404.0, 120.0167
14.540305480, 71.910, 14445.0, 120.1874
14.605504120, 71.910, 14375.0, 119.8958
14.670702760, 71.910, 14862.0, 121.9098
14.735901400, 71.910, 14779.0, 121.5689
14.801100040, 71.910, 14861.0, 121.9057
14.866298680, 71.910, 15256.0, 123.5152
14.931497320, 71.910, 15558.0, 124.7317
14.996695960, 71.910, 15745.0, 125.4791
15.061894600, 71.910, 15777.0, 125.6065
15.127093240, 71.910, 15950.0, 126.2933
15.192291880, 71.910, 16197.0, 127.2674
15.257490520, 71.910, 16463.0, 128.3082
15.322689160, 71.910, 16547.0, 128.6351
15.387887800, 71.910, 16833.0, 129.7421
15.453086440, 71.910, 16848.0, 129.7998
15.518285080, 71.910, 17186.0, 131.0954
15.583483720, 71.910, 17534.0, 132.4160
15.648682360, 71.910, 17648.0, 132.8458
15.713881000, 71.910, 17880.0, 133.7161
15.779079640, 71.910, 18323.0, 135.3625
15.844278280, 71.910, 18740.0, 136.8941
15.909476920, 71.910, 18968.0, 137.7244
15.974675560, 71.910, 18875.0, 137.3863
16.039874200, 71.910, 19404.0, 139.2982
16.105072840, 71.910, 20040.0, 141.5627
16.170271480, 71.910, 20217.0, 142.1865
16.235470120, 71.910, 20409.0, 142.8601
16.300668760, 71.910, 20744.0, 144.0278
16.365867400, 71.910, 21275.0, 145.8595
16.431066040, 71.910, 21810.0, 147.6821
16.496264680, 71.910, 22128.0, 148.7548
16.561463320, 71.910, 22584.0, 150.2797
16.626661960, 71.910, 22883.0, 151.2713
16.691860600, 71.910, 23275.0, 152.5615
16.757059240, 71.910, 23777.0, 154.1979
16.822257880, 71.910, 24153.0, 155.4124
16.887456520, 71.910, 24540.0, 156.6525
16.952655160, 71.910, 25308.0, 159.0849
17.017853800, 71.910, 25935.0, 161.0435
17.083052440, 71.910, 25989.0, 161.2110
17.148251080, 71.910, 26242.0, 161.9938
17.213449720, 71.910, 26667.0, 163.3003
17.278648360, 71.910, 27189.0, 164.8909
17.343847000, 71.910, 27997.0, 167.3230
17.409045640, 71.910, 28124.0, 167.7021
17.474244280, 71.910, 28660.0, 169.2926
17.539442920, 71.910, 29425.0, 171.5372
17.604641560, 71.910, 29810.0, 172.6557
17.669840200, 71.910, 30145.0, 173.6232
17.735038840, 71.910, 30438.0, 174.4649
17.800237480, 71.910, 30885.0, 175.7413
17.865436120, 71.910, 31293.0, 176.8983
17.930634760, 71.910, 31792.0, 178.3031
17.995833400, 71.910, 32420.0, 180.0555
18.061032040, 71.910, 32785.0, 181.0663
18.126230680, 71.910, 33074.0, 181.8626
18.191429320, 71.910, 33176.0, 182.1428
18.256627960, 71.910, 33960.0, 184.2824
18.321826600, 71.910, 34407.0, 185.4912
18.387025240, 71.910, 34616.0, 186.0538
18.452223880, 71.910, 34656.0, 186.1612
18.517422520, 71.910, 35282.0, 187.8350
18.582621160, 71.910, 35321.0, 187.9388
18.647819800, 71.910, 35714.0, 188.9815
18.713018440, 71.910, 36153.0, 190.1394
18.778217080, 71.910, 36160.0, 190.1578
18.843415720, 71.910, 36622.0, 191.3688
18.908614360, 71.910, 36886.0, 192.0573
18.973813000, 71.910, 37320.0, 193.1839
19.039011640, 71.910, 37143.0, 192.7252
19.104210280, 71.910, 37530.0, 193.7266
19.169408920, 71.910, 37423.0, 193.4503
19.234607560, 71.910, 37709.0, 194.1881
19.299806200, 71.910, 37745.0, 194.2807
19.365004840, 71.910, 37293.0, 193.1140
19.430203480, 71.910, 37632.0, 193.9897
19.495402120, 71.910, 37420.0, 193.4425
19.560600760, 71.910, 37582.0, 193.8608
19.625799400, 71.910, 37619.0, 193.9562
19.690998040, 71.910, 37278.0, 193.0751
19.756196680, 71.910, 37902.0, 194.6844
19.821395320, 71.910, 37981.0, 194.8871
19.886593960, 71.910, 38169.0, 195.3689
19.951792600, 71.910, 38195.0, 195.4354
20.016991240, 71.910, 38965.0, 197.3955
20.082189880, 71.910, 39115.0, 197.7751
20.147388520, 71.910, 39796.0, 199.4893
20.212587160, 71.910, 40688.0, 201.7127
20.277785800, 71.910, 41939.0, 204.7901
20.342984440, 71.910, 43483.0, 208.5258
20.408183080, 71.910, 45547.0, 213.4174
20.473381720, 71.910, 47811.0, 218.6573
20.538580360, 71.910, 52948.0, 230.1043
20.603779000, 71.910, 58554.0, 241.9793
20.668977640, 71.910, 67375.0, 259.5669
20.734176280, 71.910, 78878.0, 280.8523
20.799374920, 71.910, 93604.0, 305.9477
20.864573560, 71.910, 113916.0, 337.5144
20.929772200, 71.910, 138053.0, 371.5548
20.994970840, 71.910, 168257.0, 410.1914
21.060169480, 71.910, 204037.0, 451.7045
21.125368120, 71.910, 250548.0, 500.5477
21.190566760, 71.910, 311868.0, 558.4514
21.255765400, 71.910, 377675.0, 614.5527
21.320964040, 71.910, 402499.0, 634.4281
21.386162680, 71.910, 343236.0, 585.8635
21.451361320, 71.910, 233244.0, 482.9534
21.516559960, 71.910, 138012.0, 371.4997
21.581758600, 71.910, 84727.0, 291.0790
21.646957240, 71.910, 60703.0, 246.3798
21.712155880, 71.910, 48652.0, 220.5720
21.777354520, 71.910, 41931.0, 204.7706
21.842553160, 71.910, 38107.0, 195.2101
21.907751800, 71.910, 35128.0, 187.4247
21.972950440, 71.910, 33864.0, 184.0217
22.038149080, 71.910, 32167.0, 179.3516
22.103347720, 71.910, 31148.0, 176.4880
22.168546360, 71.910, 31012.0, 176.1022
22.233745000, 71.910, 30819.0, 175.5534
22.298943640, 71.910, 30491.0, 174.6167
22.364142280, 71.910, 30513.0, 174.6797
22.429340920, 71.910, 31412.0, 177.2343
22.494539560, 71.910, 31764.0, 178.2246
22.559738200, 71.910, 33355.0, 182.6335
22.624936840, 71.910, 35348.0, 188.0106
22.690135480, 71.910, 37535.0, 193.7395
22.755334120, 71.910, 40538.0, 201.3405
22.820532760, 71.910, 43733.0, 209.1244
22.885731400, 71.910, 48614.0, 220.4858
22.950930040, 71.910, 53614.0, 231.5470
23.016128680, 71.910, 60821.0, 246.6191
23.081327320, 71.910, 69545.0, 263.7139
23.146525960, 71.910, 79958.0, 282.7685
23.211724600, 71.910, 86695.0, 294.4401
23.276923240, 71.910, 86041.0, 293.3275
23.342121880, 71.910, 75358.0, 274.5141
23.407320520, 71.910, 60457.0, 245.8801
23.472519160, 71.910, 47382.0, 217.6741
23.537717800, 71.910, 37042.0, 192.4630
23.602916440, 71.910, 30200.0, 173.7815
23.668115080, 71.910, 25088.0, 158.3919
23.733313720, 71.910, 22272.0, 149.2381
23.798512360, 71.910, 20542.0, 143.3248
23.863711000, 71.910, 19395.0, 139.2659
23.928909640, 71.910, 18320.0, 135.3514
23.994108280, 71.910, 17486.0, 132.2346
24.059306920, 71.910, 16888.0, 129.9538
24.124505560, 71.910, 16613.0, 128.8914
24.189704200, 71.910, 16126.0, 126.9882
24.254902840, 71.910, 16134.0, 127.0197
24.320101480, 71.910, 15489.0, 124.4548
24.385300120, 71.910, 15378.0, 124.0081
24.450498760, 71.910, 15229.0, 123.4058
24.515697400, 71.910, 14678.0, 121.1528
24.580896040, 71.910, 14588.0, 120.7808
24.646094680, 71.910, 14524.0, 120.5156
24.711293320, 71.910, 14281.0, 119.5031
24.776491960, 71.910, 14029.0, 118.4441
24.841690600, 71.910, 13438.0, 115.9224
24.906889240, 71.910, 13459.0, 116.0129
24.972087880, 71.910, 13644.0, 116.8075
25.037286520, 71.910, 13514.0, 116.2497
25.102485160, 71.910, 13167.0, 114.7475
25.167683800, 71.910, 12718.0, 112.7741
25.232882440, 71.910, 12813.0, 113.1945
25.298081080, 71.910, 12834.0, 113.2872
25.363279720, 71.910, 12525.0, 111.9151
25.428478360, 71.910, 12391.0, 111.3149
25.493677000, 71.910, 12243.0, 110.6481
25.558875640, 71.910, 12223.0, 110.5577
25.624074280, 71.910, 12189.0, 110.4038
25.689272920, 71.910, 11826.0, 108.7474
25.754471560, 71.910, 11947.0, 109.3023
25.819670200, 71.910, 11882.0, 109.0046
25.884868840, 71.910, 11439.0, 106.9533
25.950067480, 71.910, 11441.0, 106.9626
26.015266120, 71.910, 11208.0, 105.8678
26.080464760, 71.910, 11361.0, 106.5880
26.145663400, 71.910, 11253.0, 106.0802
26.210862040, 71.910, 11103.0, 105.3708
26.276060680, 71.910, 11025.0, 105.0000
26.341259320, 71.910, 10942.0, 104.6040
26.406457960, 71.910, 10824.0, 104.0385
26.471656600, 71.910, 10756.0, 103.7111
26.536855240, 71.910, 10767.0, 103.7642
26.602053880, 71.910, 10541.0, 102.6694
26.667252520, 71.910, 10643.0, 103.1649
26.732451160, 71.910, 10481.0, 102.3768
26.797649800, 71.910, 10510.0, 102.5183
26.862848440, 71.910, 10375.0, 101.8577
26.928047080, 71.910, 10202.0, 101.0050
26.993245720, 71.910, 10241.0, 101.1978
27.058444360, 71.910, 10156.0, 100.7770
27.123643000, 71.910, 10005.0, 100.0250
27.188841640, 71.910, 10066.0, 100.3295
27.254040280, 71.910, 10003.0, 100.0150
27.319238920, 71.910, 9838.0, 99.1867
27.384437560, 71.910, 9759.0, 98.7877
27.449636200, 71.910, 9692.0, 98.4480
27.514834840, 71.910, 9843.0, 99.2119
27.580033480, 71.910, 9532.0, 97.6320
27.645232120, 71.910, 9589.0, 97.9234
27.710430760, 71.910, 9694.0, 98.4581
27.775629400, 71.910, 9644.0, 98.2039
27.840828040, 71.910, 9665.0, 98.3107
27.906026680, 71.910, 9457.0, 97.2471
27.971225320, 71.910, 9652.0, 98.2446
28.036423960, 71.910, 9362.0, 96.7574
28.101622600, 71.910, 9393.0, 96.9175
28.166821240, 71.910, 9447.0, 97.1957
28.232019880, 71.910, 9292.0, 96.3950
28.297218520, 71.910, 9288.0, 96.3743
28.362417160, 71.910, 9399.0, 96.9484
28.427615800, 71.910, 9350.0, 96.6954
28.492814440, 71.910, 9454.0, 97.2317
28.558013080, 71.910, 9375.0, 96.8246
28.623211720, 71.910, 9261.0, 96.2341
28.688410360, 71.910, 9325.0, 96.5660
28.753609000, 71.910, 9435.0, 97.1339
28.818807640, 71.910, 9414.0, 97.0258
28.884006280, 71.910, 9488.0, 97.4064
28.949204920, 71.910, 9775.0, 98.8686
29.014403560, 71.910, 9942.0, 99.7096
29.079602200, 71.910, 10119.0, 100.5932
29.144800840, 71.910, 10364.0, 101.8037
29.209999480, 71.910, 10623.0, 103.0679
29.275198120, 71.910, 10977.0, 104.7712
29.340396760, 71.910, 11153.0, 105.6078
29.405595400, 71.910, 11638.0, 107.8796
29.470794040, 71.910, 11920.0, 109.1788
29.535992680, 71.910, 11843.0, 108.8255
29.601191320, 71.910, 11225.0, 105.9481
29.666389960, 71.910, 10593.0, 102.9223
29.731588600, 71.910, 9878.0, 99.3881
29.796787240, 71.910, 9547.0, 97.7088
29.861985880, 71.910, 9048.0, 95.1210
29.927184520, 71.910, 8991.0, 94.8209
29.992383160, 71.910, 9003.0, 94.8841
30.057581800, 71.910, 8731.0, 93.4398
30.122780440, 71.910, 8695.0, 93.2470
30.187979080, 71.910, 8731.0, 93.4398
30.253177720, 71.910, 8791.0, 93.7603
30.318376360, 71.910, 8734.0, 93.4559
30.383575000, 71.910, 8668.0, 93.1021
30.448773640, 71.910, 8553.0, 92.4824
30.513972280, 71.910, 8626.0, 92.8763
30.579170920, 71.910, 8409.0, 91.7006
30.644369560, 71.910, 8578.0, 92.6175
30.709568200, 71.910, 8409.0, 91.7006
30.774766840, 71.910, 8667.0, 93.0967
30.839965480, 71.910, 8637.0, 92.9355
30.905164120, 71.910, 8537.0, 92.3959
30.970362760, 71.910, 8601.0, 92.7416
31.035561400, 71.910, 8471.0, 92.0380
31.100760040, 71.910, 8546.0, 92.4446
31.165958680, 71.910, 8385.0, 91.5696
31.231157320, 71.910, 8360.0, 91.4330
31.296355960, 71.910, 8490.0, 92.1412
31.361554600, 71.910, 8398.0, 91.6406
31.426753240, 71.910, 8623.0, 92.8601
31.491951880, 71.910, 8650.0, 93.0054
31.557150520, 71.910, 8439.0, 91.8640
31.622349160, 71.910, 8434.0, 91.8368
31.687547800, 71.910, 8684.0, 93.1880
31.752746440, 71.910, 8605.0, 92.7631
31.817945080, 71.910, 8459.0, 91.9728
31.883143720, 71.910, 8360.0, 91.4330
31.948342360, 71.910, 8496.0, 92.1737
32.013541000, 71.910, 8260.0, 90.8845
32.078739640, 71.910, 8505.0, 92.2226
32.143938280, 71.910, 8586.0, 92.6607
32.209136920, 71.910, 8445.0, 91.8967
32.274335560, 71.910, 8637.0, 92.9355
32.339534200, 71.910, 8606.0, 92.7685
32.404732840, 71.910, 8504.0, 92.2171
32.469931480, 71.910, 8584.0, 92.6499
32.535130120, 71.910, 8527.0, 92.3418
32.600328760, 71.910, 8474.0, 92.0543
32.665527400, 71.910, 8620.0, 92.8440
32.730726040, 71.910, 8536.0, 92.3905
32.795924680, 71.910, 8520.0, 92.3038
32.861123320, 71.910, 8559.0, 92.5149
32.926321960, 71.910, 8700.0, 93.2738
32.991520600, 71.910, 8552.0, 92.4770
33.056719240, 71.910, 8691.0, 93.2255
33.121917880, 71.910, 8581.0, 92.6337
33.187116520, 71.910, 8542.0, 92.4229
33.252315160, 71.910, 8703.0, 93.2899
33.317513800, 71.910, 8683.0, 93.1826
33.382712440, 71.910, 8683.0, 93.1826
33.447911080, 71.910, 8622.0, 92.8547
33.513109720, 71.910, 8567.0, 92.5581
33.578308360, 71.910, 8484.0, 92.1086
33.643507000, 71.910, 8614.0, 92.8116
33.708705640, 71.910, 8558.0, 92.5095
33.773904280, 71.910, 8720.0, 93.3809
33.839102920, 71.910, 8594.0, 92.7038
33.904301560, 71.910, 8661.0, 93.0645
33.969500200, 71.910, 8775.0, 93.6750
34.034698840, 71.910, 8684.0, 93.1880
34.099897480, 71.910, 8769.0, 93.6429
34.165096120, 71.910, 8791.0, 93.7603
34.230294760, 71.910, 8910.0, 94.3928
34.295493400, 71.910, 8980.0, 94.7629
34.360692040, 71.910, 8870.0, 94.1807
34.425890680, 71.910, 8797.0, 93.7923
34.491089320, 71.910, 8887.0, 94.2709
34.556287960, 71.910, 8842.0, 94.0319
34.621486600, 71.910, 8890.0, 94.2868
34.686685240, 71.910, 8961.0, 94.6626
34.751883880, 71.910, 9021.0, 94.9789
34.817082520, 71.910, 8974.0, 94.7312
34.882281160, 71.910, 9033.0, 95.0421
34.947479800, 71.910, 9006.0, 94.8999
35.012678440, 71.910, 9124.0, 95.5196
35.077877080, 71.910, 9034.0, 95.0474
35.143075720, 71.910, 9231.0, 96.0781
35.208274360, 71.910, 9317.0, 96.5246
35.273473000, 71.910, 9395.0, 96.9278
35.338671640, 71.910, 9494.0, 97.4372
35.403870280, 71.910, 9703.0, 98.5038
35.469068920, 71.910, 10093.0, 100.4639
35.534267560, 71.910, 10837.0, 104.1009
35.599466200, 71.910, 11676.0, 108.0555
35.664664840, 71.910, 12783.0, 113.0619
35.729863480, 71.910, 13655.0, 116.8546
35.795062120, 71.910, 14915.0, 122.1270
35.860260760, 71.910, 15927.0, 126.2022
35.925459400, 71.910, 17322.0, 131.6131
35.990658040, 71.910, 18892.0, 137.4482
36.055856680, 71.910, 19872.0, 140.9681
36.121055320, 71.910, 20681.0, 143.8089
36.186253960, 71.910, 19907.0, 141.0922
36.251452600, 71.910, 18159.0, 134.7553
36.316651240, 71.910, 15682.0, 125.2278
36.381849880, 71.910, 13528.0, 116.3099
36.447048520, 71.910, 11928.0, 109.2154
36.512247160, 71.910, 10944.0, 104.6136
36.577445800, 71.910, 10267.0, 101.3262
36.642644440, 71.910, 9899.0, 99.4937
36.707843080, 71.910, 9449.0, 97.2060
36.773041720, 71.910, 9425.0, 97.0824
36.838240360, 71.910, 9507.0, 97.5038
36.903439000, 71.910, 9505.0, 97.4936
36.968637640, 71.910, 9485.0, 97.3910
37.033836280, 71.910, 9294.0, 96.4054
37.099034920, 71.910, 9319.0, 96.5350
37.164233560, 71.910, 9366.0, 96.7781
37.229432200, 71.910, 9206.0, 95.9479
37.294630840, 71.910, 9233.0, 96.0885
37.359829480, 71.910, 9460.0, 97.2625
37.425028120, 71.910, 9486.0, 97.3961
37.490226760, 71.910, 9664.0, 98.3056
37.555425400, 71.910, 9598.0, 97.9694
37.620624040, 71.910, 9580.0, 97.8775
37.685822680, 71.910, 9820.0, 99.0959
37.751021320, 71.910, 10216.0, 101.0742
37.816219960, 71.910, 10015.0, 100.0750
37.881418600, 71.910, 10039.0, 100.1948
37.946617240, 71.910, 10138.0, 100.6876
38.011815880, 71.910, 10226.0, 101.1237
38.077014520, 71.910, 10524.0, 102.5865
38.142213160, 71.910, 10476.0, 102.3523
38.207411800, 71.910, 10486.0, 102.4012
38.272610440, 71.910, 10106.0, 100.5286
38.337809080, 71.910, 10007.0, 100.0350
38.403007720, 71.910, 9752.0, 98.7522
38.468206360, 71.910, 9654.0, 98.2548
38.533405000, 71.910, 9864.0, 99.3177
38.598603640, 71.910, 9669.0, 98.3311
38.663802280, 71.910, 9643.0, 98.1988
38.729000920, 71.910, 9875.0, 99.3730
38.794199560, 71.910, 9838.0, 99.1867
38.859398200, 71.910, 9887.0, 99.4334
38.924596840, 71.910, 10291.0, 101.4446
38.989795480, 71.910, 10629.0, 103.0970
39.054994120, 71.910, 11024.0, 104.9952
39.120192760, 71.910, 11299.0, 106.2968
39.185391400, 71.910, 12175.0, 110.3404
39.250590040, 71.910, 12608.0, 112.2854
39.315788680, 71.910, 13384.0, 115.6892
39.380987320, 71.910, 14333.0, 119.7205
39.446185960, 71.910, 15340.0, 123.8548
39.511384600, 71.910, 15688.0, 125.2517
39.576583240, 71.910, 16301.0, 127.6754
39.641781880, 71.910, 16956.0, 130.2152
39.706980520, 71.910, 17006.0, 130.4071
39.772179160, 71.910, 16801.0, 129.6187
39.837377800, 71.910, 16121.0, 126.9685
39.902576440, 71.910, 14945.0, 122.2497
39.967775080, 71.910, 13830.0, 117.6010