File: Chapter4_Crystallinity-measurement/data/XRD/heated/PEEK500907_30C_after_1.csv
[Measurement conditions]
Sample identification,PEEK500907_30C_after_1
Comment,
Anode material,Cu
K-Alpha1 wavelength,1.5405980
K-Alpha2 wavelength,1.5444260
Ratio K-Alpha2/K-Alpha1,0.500
Divergence slit,Fixed,0.76mm
Monochromator used,NO
Generator voltage, 40
Tube current, 15
File date and time,12/Jun/2025 13:22
Unit cell,
h k l, 0 0 0
Scan axis,Gonio
Scan range,10.009000000,40.000374400
Scan step size,0.0651986
No. of points, 460
Scan type,CONTINUOUS
Time per step,71.910
[Scan points]
Angle, TimePerStep, Intensity, ESD
10.041599320, 71.910, 4477.0, 66.9104
10.106797960, 71.910, 4533.0, 67.3276
10.171996600, 71.910, 4571.0, 67.6092
10.237195240, 71.910, 4461.0, 66.7907
10.302393880, 71.910, 4534.0, 67.3350
10.367592520, 71.910, 4545.0, 67.4166
10.432791160, 71.910, 4515.0, 67.1937
10.497989800, 71.910, 4316.0, 65.6963
10.563188440, 71.910, 4656.0, 68.2349
10.628387080, 71.910, 4531.0, 67.3127
10.693585720, 71.910, 4309.0, 65.6430
10.758784360, 71.910, 4436.0, 66.6033
10.823983000, 71.910, 4474.0, 66.8880
10.889181640, 71.910, 4442.0, 66.6483
10.954380280, 71.910, 4474.0, 66.8880
11.019578920, 71.910, 4371.0, 66.1135
11.084777560, 71.910, 4375.0, 66.1438
11.149976200, 71.910, 4364.0, 66.0606
11.215174840, 71.910, 4464.0, 66.8132
11.280373480, 71.910, 4500.0, 67.0820
11.345572120, 71.910, 4379.0, 66.1740
11.410770760, 71.910, 4404.0, 66.3626
11.475969400, 71.910, 4431.0, 66.5658
11.541168040, 71.910, 4436.0, 66.6033
11.606366680, 71.910, 4462.0, 66.7982
11.671565320, 71.910, 4472.0, 66.8730
11.736763960, 71.910, 4350.0, 65.9545
11.801962600, 71.910, 4484.0, 66.9627
11.867161240, 71.910, 4506.0, 67.1267
11.932359880, 71.910, 4468.0, 66.8431
11.997558520, 71.910, 4454.0, 66.7383
12.062757160, 71.910, 4501.0, 67.0895
12.127955800, 71.910, 4464.0, 66.8132
12.193154440, 71.910, 4449.0, 66.7008
12.258353080, 71.910, 4697.0, 68.5347
12.323551720, 71.910, 4481.0, 66.9403
12.388750360, 71.910, 4415.0, 66.4455
12.453949000, 71.910, 4485.0, 66.9701
12.519147640, 71.910, 4480.0, 66.9328
12.584346280, 71.910, 4414.0, 66.4379
12.649544920, 71.910, 4491.0, 67.0149
12.714743560, 71.910, 4521.0, 67.2384
12.779942200, 71.910, 4530.0, 67.3053
12.845140840, 71.910, 4447.0, 66.6858
12.910339480, 71.910, 4627.0, 68.0221
12.975538120, 71.910, 4570.0, 67.6018
13.040736760, 71.910, 4660.0, 68.2642
13.105935400, 71.910, 4740.0, 68.8477
13.171134040, 71.910, 4771.0, 69.0724
13.236332680, 71.910, 4744.0, 68.8767
13.301531320, 71.910, 4743.0, 68.8694
13.366729960, 71.910, 4742.0, 68.8622
13.431928600, 71.910, 4704.0, 68.5857
13.497127240, 71.910, 4876.0, 69.8284
13.562325880, 71.910, 4846.0, 69.6132
13.627524520, 71.910, 4830.0, 69.4982
13.692723160, 71.910, 4915.0, 70.1071
13.757921800, 71.910, 4941.0, 70.2922
13.823120440, 71.910, 4991.0, 70.6470
13.888319080, 71.910, 5093.0, 71.3653
13.953517720, 71.910, 5156.0, 71.8053
14.018716360, 71.910, 5154.0, 71.7914
14.083915000, 71.910, 5055.0, 71.0985
14.149113640, 71.910, 5309.0, 72.8629
14.214312280, 71.910, 5316.0, 72.9109
14.279510920, 71.910, 5320.0, 72.9383
14.344709560, 71.910, 5296.0, 72.7736
14.409908200, 71.910, 5294.0, 72.7599
14.475106840, 71.910, 5329.0, 73.0000
14.540305480, 71.910, 5501.0, 74.1687
14.605504120, 71.910, 5498.0, 74.1485
14.670702760, 71.910, 5402.0, 73.4983
14.735901400, 71.910, 5545.0, 74.4648
14.801100040, 71.910, 5716.0, 75.6042
14.866298680, 71.910, 5740.0, 75.7628
14.931497320, 71.910, 5852.0, 76.4984
14.996695960, 71.910, 5838.0, 76.4068
15.061894600, 71.910, 6009.0, 77.5177
15.127093240, 71.910, 5843.0, 76.4395
15.192291880, 71.910, 5856.0, 76.5245
15.257490520, 71.910, 6142.0, 78.3709
15.322689160, 71.910, 6166.0, 78.5239
15.387887800, 71.910, 6373.0, 79.8311
15.453086440, 71.910, 6148.0, 78.4092
15.518285080, 71.910, 6370.0, 79.8123
15.583483720, 71.910, 6411.0, 80.0687
15.648682360, 71.910, 6638.0, 81.4739
15.713881000, 71.910, 6535.0, 80.8393
15.779079640, 71.910, 6625.0, 81.3941
15.844278280, 71.910, 6800.0, 82.4621
15.909476920, 71.910, 6906.0, 83.1023
15.974675560, 71.910, 6901.0, 83.0723
16.039874200, 71.910, 6890.0, 83.0060
16.105072840, 71.910, 7181.0, 84.7408
16.170271480, 71.910, 7125.0, 84.4097
16.235470120, 71.910, 7233.0, 85.0470
16.300668760, 71.910, 7301.0, 85.4459
16.365867400, 71.910, 7416.0, 86.1162
16.431066040, 71.910, 7474.0, 86.4523
16.496264680, 71.910, 7826.0, 88.4647
16.561463320, 71.910, 7667.0, 87.5614
16.626661960, 71.910, 7700.0, 87.7496
16.691860600, 71.910, 7878.0, 88.7581
16.757059240, 71.910, 7801.0, 88.3233
16.822257880, 71.910, 8166.0, 90.3659
16.887456520, 71.910, 8215.0, 90.6366
16.952655160, 71.910, 8026.0, 89.5879
17.017853800, 71.910, 8363.0, 91.4494
17.083052440, 71.910, 8288.0, 91.0385
17.148251080, 71.910, 8678.0, 93.1558
17.213449720, 71.910, 8763.0, 93.6109
17.278648360, 71.910, 8956.0, 94.6361
17.343847000, 71.910, 9007.0, 94.9052
17.409045640, 71.910, 9038.0, 95.0684
17.474244280, 71.910, 9367.0, 96.7833
17.539442920, 71.910, 9546.0, 97.7036
17.604641560, 71.910, 9898.0, 99.4887
17.669840200, 71.910, 10002.0, 100.0100
17.735038840, 71.910, 10354.0, 101.7546
17.800237480, 71.910, 10639.0, 103.1455
17.865436120, 71.910, 11055.0, 105.1428
17.930634760, 71.910, 11647.0, 107.9213
17.995833400, 71.910, 12518.0, 111.8839
18.061032040, 71.910, 13313.0, 115.3820
18.126230680, 71.910, 14166.0, 119.0210
18.191429320, 71.910, 15112.0, 122.9309
18.256627960, 71.910, 16370.0, 127.9453
18.321826600, 71.910, 17540.0, 132.4387
18.387025240, 71.910, 18279.0, 135.1999
18.452223880, 71.910, 18551.0, 136.2021
18.517422520, 71.910, 18948.0, 137.6517
18.582621160, 71.910, 19016.0, 137.8985
18.647819800, 71.910, 18867.0, 137.3572
18.713018440, 71.910, 18182.0, 134.8406
18.778217080, 71.910, 17785.0, 133.3604
18.843415720, 71.910, 16975.0, 130.2881
18.908614360, 71.910, 16267.0, 127.5421
18.973813000, 71.910, 15571.0, 124.7838
19.039011640, 71.910, 15059.0, 122.7151
19.104210280, 71.910, 14249.0, 119.3692
19.169408920, 71.910, 13723.0, 117.1452
19.234607560, 71.910, 13485.0, 116.1249
19.299806200, 71.910, 12879.0, 113.4857
19.365004840, 71.910, 12304.0, 110.9234
19.430203480, 71.910, 12026.0, 109.6631
19.495402120, 71.910, 11860.0, 108.9036
19.560600760, 71.910, 11424.0, 106.8831
19.625799400, 71.910, 11341.0, 106.4941
19.690998040, 71.910, 11420.0, 106.8644
19.756196680, 71.910, 11000.0, 104.8809
19.821395320, 71.910, 11147.0, 105.5794
19.886593960, 71.910, 11469.0, 107.0934
19.951792600, 71.910, 11434.0, 106.9299
20.016991240, 71.910, 11664.0, 108.0000
20.082189880, 71.910, 11624.0, 107.8147
20.147388520, 71.910, 12175.0, 110.3404
20.212587160, 71.910, 12067.0, 109.8499
20.277785800, 71.910, 12528.0, 111.9285
20.342984440, 71.910, 12691.0, 112.6543
20.408183080, 71.910, 12829.0, 113.2652
20.473381720, 71.910, 12807.0, 113.1680
20.538580360, 71.910, 13063.0, 114.2935
20.603779000, 71.910, 12886.0, 113.5165
20.668977640, 71.910, 12798.0, 113.1282
20.734176280, 71.910, 12698.0, 112.6854
20.799374920, 71.910, 12368.0, 111.2115
20.864573560, 71.910, 12214.0, 110.5170
20.929772200, 71.910, 11683.0, 108.0879
20.994970840, 71.910, 11764.0, 108.4620
21.060169480, 71.910, 11116.0, 105.4324
21.125368120, 71.910, 11022.0, 104.9857
21.190566760, 71.910, 10854.0, 104.1825
21.255765400, 71.910, 10736.0, 103.6147
21.320964040, 71.910, 10459.0, 102.2693
21.386162680, 71.910, 10593.0, 102.9223
21.451361320, 71.910, 10565.0, 102.7862
21.516559960, 71.910, 10432.0, 102.1372
21.581758600, 71.910, 10440.0, 102.1763
21.646957240, 71.910, 10375.0, 101.8577
21.712155880, 71.910, 10612.0, 103.0146
21.777354520, 71.910, 10770.0, 103.7786
21.842553160, 71.910, 11273.0, 106.1744
21.907751800, 71.910, 11523.0, 107.3452
21.972950440, 71.910, 12248.0, 110.6707
22.038149080, 71.910, 12185.0, 110.3857
22.103347720, 71.910, 12905.0, 113.6002
22.168546360, 71.910, 13039.0, 114.1884
22.233745000, 71.910, 13497.0, 116.1766
22.298943640, 71.910, 13526.0, 116.3013
22.364142280, 71.910, 13746.0, 117.2433
22.429340920, 71.910, 13601.0, 116.6233
22.494539560, 71.910, 13421.0, 115.8490
22.559738200, 71.910, 13291.0, 115.2866
22.624936840, 71.910, 12723.0, 112.7963
22.690135480, 71.910, 12458.0, 111.6154
22.755334120, 71.910, 12069.0, 109.8590
22.820532760, 71.910, 11936.0, 109.2520
22.885731400, 71.910, 11448.0, 106.9953
22.950930040, 71.910, 11197.0, 105.8159
23.016128680, 71.910, 10796.0, 103.9038
23.081327320, 71.910, 10528.0, 102.6060
23.146525960, 71.910, 10094.0, 100.4689
23.211724600, 71.910, 9740.0, 98.6914
23.276923240, 71.910, 9520.0, 97.5705
23.342121880, 71.910, 9277.0, 96.3172
23.407320520, 71.910, 9064.0, 95.2050
23.472519160, 71.910, 8942.0, 94.5621
23.537717800, 71.910, 8582.0, 92.6391
23.602916440, 71.910, 8298.0, 91.0934
23.668115080, 71.910, 8296.0, 91.0824
23.733313720, 71.910, 8205.0, 90.5815
23.798512360, 71.910, 7844.0, 88.5664
23.863711000, 71.910, 7926.0, 89.0281
23.928909640, 71.910, 7836.0, 88.5212
23.994108280, 71.910, 7850.0, 88.6002
24.059306920, 71.910, 7551.0, 86.8965
24.124505560, 71.910, 7352.0, 85.7438
24.189704200, 71.910, 7292.0, 85.3932
24.254902840, 71.910, 7274.0, 85.2877
24.320101480, 71.910, 7292.0, 85.3932
24.385300120, 71.910, 7124.0, 84.4038
24.450498760, 71.910, 7128.0, 84.4275
24.515697400, 71.910, 7031.0, 83.8511
24.580896040, 71.910, 7069.0, 84.0773
24.646094680, 71.910, 7162.0, 84.6286
24.711293320, 71.910, 6999.0, 83.6600
24.776491960, 71.910, 7064.0, 84.0476
24.841690600, 71.910, 7046.0, 83.9405
24.906889240, 71.910, 7161.0, 84.6227
24.972087880, 71.910, 6988.0, 83.5943
25.037286520, 71.910, 7121.0, 84.3860
25.102485160, 71.910, 7101.0, 84.2674
25.167683800, 71.910, 7131.0, 84.4452
25.232882440, 71.910, 6935.0, 83.2766
25.298081080, 71.910, 7049.0, 83.9583
25.363279720, 71.910, 6991.0, 83.6122
25.428478360, 71.910, 7164.0, 84.6404
25.493677000, 71.910, 7091.0, 84.2081
25.558875640, 71.910, 7086.0, 84.1784
25.624074280, 71.910, 7128.0, 84.4275
25.689272920, 71.910, 7101.0, 84.2674
25.754471560, 71.910, 7048.0, 83.9524
25.819670200, 71.910, 7058.0, 84.0119
25.884868840, 71.910, 6973.0, 83.5045
25.950067480, 71.910, 7061.0, 84.0298
26.015266120, 71.910, 6884.0, 82.9699
26.080464760, 71.910, 6892.0, 83.0181
26.145663400, 71.910, 6998.0, 83.6540
26.210862040, 71.910, 6857.0, 82.8070
26.276060680, 71.910, 6876.0, 82.9216
26.341259320, 71.910, 6678.0, 81.7190
26.406457960, 71.910, 6772.0, 82.2922
26.471656600, 71.910, 6952.0, 83.3787
26.536855240, 71.910, 6948.0, 83.3547
26.602053880, 71.910, 6917.0, 83.1685
26.667252520, 71.910, 6817.0, 82.5651
26.732451160, 71.910, 6825.0, 82.6136
26.797649800, 71.910, 6814.0, 82.5470
26.862848440, 71.910, 6774.0, 82.3043
26.928047080, 71.910, 6797.0, 82.4439
26.993245720, 71.910, 6991.0, 83.6122
27.058444360, 71.910, 6908.0, 83.1144
27.123643000, 71.910, 6997.0, 83.6481
27.188841640, 71.910, 6826.0, 82.6196
27.254040280, 71.910, 6989.0, 83.6002
27.319238920, 71.910, 7145.0, 84.5281
27.384437560, 71.910, 6968.0, 83.4745
27.449636200, 71.910, 7286.0, 85.3581
27.514834840, 71.910, 7197.0, 84.8351
27.580033480, 71.910, 7166.0, 84.6522
27.645232120, 71.910, 7451.0, 86.3192
27.710430760, 71.910, 7606.0, 87.2124
27.775629400, 71.910, 7630.0, 87.3499
27.840828040, 71.910, 7795.0, 88.2893
27.906026680, 71.910, 7980.0, 89.3308
27.971225320, 71.910, 8229.0, 90.7138
28.036423960, 71.910, 8320.0, 91.2140
28.101622600, 71.910, 8599.0, 92.7308
28.166821240, 71.910, 8933.0, 94.5145
28.232019880, 71.910, 9026.0, 95.0053
28.297218520, 71.910, 9286.0, 96.3639
28.362417160, 71.910, 9494.0, 97.4372
28.427615800, 71.910, 9496.0, 97.4474
28.492814440, 71.910, 9500.0, 97.4679
28.558013080, 71.910, 9490.0, 97.4166
28.623211720, 71.910, 9243.0, 96.1405
28.688410360, 71.910, 9376.0, 96.8297
28.753609000, 71.910, 9107.0, 95.4306
28.818807640, 71.910, 9049.0, 95.1262
28.884006280, 71.910, 8824.0, 93.9361
28.949204920, 71.910, 8635.0, 92.9247
29.014403560, 71.910, 8452.0, 91.9348
29.079602200, 71.910, 8438.0, 91.8586
29.144800840, 71.910, 8177.0, 90.4268
29.209999480, 71.910, 8042.0, 89.6772
29.275198120, 71.910, 7959.0, 89.2132
29.340396760, 71.910, 7835.0, 88.5155
29.405595400, 71.910, 7820.0, 88.4308
29.470794040, 71.910, 7644.0, 87.4300
29.535992680, 71.910, 7710.0, 87.8066
29.601191320, 71.910, 7674.0, 87.6014
29.666389960, 71.910, 7497.0, 86.5852
29.731588600, 71.910, 7478.0, 86.4754
29.796787240, 71.910, 7421.0, 86.1452
29.861985880, 71.910, 7400.0, 86.0233
29.927184520, 71.910, 7595.0, 87.1493
29.992383160, 71.910, 7295.0, 85.4108
30.057581800, 71.910, 7478.0, 86.4754
30.122780440, 71.910, 7253.0, 85.1645
30.187979080, 71.910, 7354.0, 85.7555
30.253177720, 71.910, 7325.0, 85.5862
30.318376360, 71.910, 7335.0, 85.6446
30.383575000, 71.910, 7339.0, 85.6680
30.448773640, 71.910, 7073.0, 84.1011
30.513972280, 71.910, 7050.0, 83.9643
30.579170920, 71.910, 7025.0, 83.8153
30.644369560, 71.910, 7115.0, 84.3505
30.709568200, 71.910, 7085.0, 84.1724
30.774766840, 71.910, 7083.0, 84.1606
30.839965480, 71.910, 6944.0, 83.3307
30.905164120, 71.910, 7029.0, 83.8391
30.970362760, 71.910, 7203.0, 84.8705
31.035561400, 71.910, 7091.0, 84.2081
31.100760040, 71.910, 7152.0, 84.5695
31.165958680, 71.910, 7076.0, 84.1190
31.231157320, 71.910, 7125.0, 84.4097
31.296355960, 71.910, 7122.0, 84.3919
31.361554600, 71.910, 7012.0, 83.7377
31.426753240, 71.910, 7121.0, 84.3860
31.491951880, 71.910, 7205.0, 84.8823
31.557150520, 71.910, 7221.0, 84.9765
31.622349160, 71.910, 7356.0, 85.7671
31.687547800, 71.910, 7091.0, 84.2081
31.752746440, 71.910, 7232.0, 85.0412
31.817945080, 71.910, 7256.0, 85.1822
31.883143720, 71.910, 7053.0, 83.9821
31.948342360, 71.910, 7341.0, 85.6796
32.013541000, 71.910, 7352.0, 85.7438
32.078739640, 71.910, 7477.0, 86.4696
32.143938280, 71.910, 7527.0, 86.7583
32.209136920, 71.910, 7579.0, 87.0575
32.274335560, 71.910, 7557.0, 86.9310
32.339534200, 71.910, 7720.0, 87.8635
32.404732840, 71.910, 7582.0, 87.0747
32.469931480, 71.910, 7569.0, 87.0000
32.535130120, 71.910, 7491.0, 86.5506
32.600328760, 71.910, 7585.0, 87.0919
32.665527400, 71.910, 7444.0, 86.2786
32.730726040, 71.910, 7710.0, 87.8066
32.795924680, 71.910, 7590.0, 87.1206
32.861123320, 71.910, 7800.0, 88.3176
32.926321960, 71.910, 7530.0, 86.7756
32.991520600, 71.910, 7560.0, 86.9483
33.056719240, 71.910, 7558.0, 86.9368
33.121917880, 71.910, 7713.0, 87.8237
33.187116520, 71.910, 7579.0, 87.0575
33.252315160, 71.910, 7631.0, 87.3556
33.317513800, 71.910, 7612.0, 87.2468
33.382712440, 71.910, 7692.0, 87.7040
33.447911080, 71.910, 7515.0, 86.6891
33.513109720, 71.910, 7558.0, 86.9368
33.578308360, 71.910, 7563.0, 86.9655
33.643507000, 71.910, 7712.0, 87.8180
33.708705640, 71.910, 7525.0, 86.7468
33.773904280, 71.910, 7476.0, 86.4639
33.839102920, 71.910, 7634.0, 87.3728
33.904301560, 71.910, 7422.0, 86.1510
33.969500200, 71.910, 7486.0, 86.5217
34.034698840, 71.910, 7416.0, 86.1162
34.099897480, 71.910, 7440.0, 86.2554
34.165096120, 71.910, 7297.0, 85.4225
34.230294760, 71.910, 7509.0, 86.6545
34.295493400, 71.910, 7342.0, 85.6855
34.360692040, 71.910, 7417.0, 86.1220
34.425890680, 71.910, 7303.0, 85.4576
34.491089320, 71.910, 7387.0, 85.9477
34.556287960, 71.910, 7396.0, 86.0000
34.621486600, 71.910, 7479.0, 86.4812
34.686685240, 71.910, 7273.0, 85.2819
34.751883880, 71.910, 7268.0, 85.2526
34.817082520, 71.910, 7374.0, 85.8720
34.882281160, 71.910, 7285.0, 85.3522
34.947479800, 71.910, 7287.0, 85.3639
35.012678440, 71.910, 7335.0, 85.6446
35.077877080, 71.910, 7152.0, 84.5695
35.143075720, 71.910, 7316.0, 85.5336
35.208274360, 71.910, 7372.0, 85.8604
35.273473000, 71.910, 7427.0, 86.1800
35.338671640, 71.910, 7311.0, 85.5044
35.403870280, 71.910, 7314.0, 85.5219
35.469068920, 71.910, 7331.0, 85.6213
35.534267560, 71.910, 7349.0, 85.7263
35.599466200, 71.910, 7256.0, 85.1822
35.664664840, 71.910, 7199.0, 84.8469
35.729863480, 71.910, 7243.0, 85.1058
35.795062120, 71.910, 7350.0, 85.7321
35.860260760, 71.910, 7196.0, 84.8292
35.925459400, 71.910, 7113.0, 84.3386
35.990658040, 71.910, 7231.0, 85.0353
36.055856680, 71.910, 7142.0, 84.5104
36.121055320, 71.910, 7303.0, 85.4576
36.186253960, 71.910, 7429.0, 86.1916
36.251452600, 71.910, 7274.0, 85.2877
36.316651240, 71.910, 7383.0, 85.9244
36.381849880, 71.910, 7208.0, 84.8999
36.447048520, 71.910, 7175.0, 84.7054
36.512247160, 71.910, 7241.0, 85.0941
36.577445800, 71.910, 7206.0, 84.8882
36.642644440, 71.910, 7259.0, 85.1998
36.707843080, 71.910, 7319.0, 85.5512
36.773041720, 71.910, 7396.0, 86.0000
36.838240360, 71.910, 7280.0, 85.3229
36.903439000, 71.910, 7278.0, 85.3112
36.968637640, 71.910, 7425.0, 86.1684
37.033836280, 71.910, 7229.0, 85.0235
37.099034920, 71.910, 7250.0, 85.1469
37.164233560, 71.910, 7407.0, 86.0639
37.229432200, 71.910, 7268.0, 85.2526
37.294630840, 71.910, 7415.0, 86.1104
37.359829480, 71.910, 7460.0, 86.3713
37.425028120, 71.910, 7411.0, 86.0872
37.490226760, 71.910, 7371.0, 85.8545
37.555425400, 71.910, 7197.0, 84.8351
37.620624040, 71.910, 7555.0, 86.9195
37.685822680, 71.910, 7518.0, 86.7064
37.751021320, 71.910, 7391.0, 85.9709
37.816219960, 71.910, 7465.0, 86.4002
37.881418600, 71.910, 7742.0, 87.9886
37.946617240, 71.910, 7362.0, 85.8021
38.011815880, 71.910, 7498.0, 86.5910
38.077014520, 71.910, 7582.0, 87.0747
38.142213160, 71.910, 7602.0, 87.1894
38.207411800, 71.910, 7724.0, 87.8863
38.272610440, 71.910, 7708.0, 87.7952
38.337809080, 71.910, 7759.0, 88.0852
38.403007720, 71.910, 7752.0, 88.0454
38.468206360, 71.910, 7743.0, 87.9943
38.533405000, 71.910, 7757.0, 88.0738
38.598603640, 71.910, 7956.0, 89.1964
38.663802280, 71.910, 7776.0, 88.1816
38.729000920, 71.910, 7839.0, 88.5381
38.794199560, 71.910, 7683.0, 87.6527
38.859398200, 71.910, 7937.0, 89.0898
38.924596840, 71.910, 7748.0, 88.0227
38.989795480, 71.910, 7914.0, 88.9607
39.054994120, 71.910, 7742.0, 87.9886
39.120192760, 71.910, 7759.0, 88.0852
39.185391400, 71.910, 7626.0, 87.3270
39.250590040, 71.910, 7702.0, 87.7610
39.315788680, 71.910, 7720.0, 87.8635
39.380987320, 71.910, 7371.0, 85.8545
39.446185960, 71.910, 7607.0, 87.2181
39.511384600, 71.910, 7305.0, 85.4693
39.576583240, 71.910, 7583.0, 87.0804
39.641781880, 71.910, 7540.0, 86.8332
39.706980520, 71.910, 7523.0, 86.7352
39.772179160, 71.910, 7569.0, 87.0000
39.837377800, 71.910, 7302.0, 85.4517
39.902576440, 71.910, 7640.0, 87.4071
39.967775080, 71.910, 7646.0, 87.4414