File: Chapter4_Crystallinity-measurement/data/XRD/heated/PEEK500907_200C_1.csv
[Measurement conditions]
Sample identification,PEEK500907_200C_1
Comment,
Anode material,Cu
K-Alpha1 wavelength,1.5405980
K-Alpha2 wavelength,1.5444260
Ratio K-Alpha2/K-Alpha1,0.500
Divergence slit,Fixed,0.76mm
Monochromator used,NO
Generator voltage, 40
Tube current, 15
File date and time,12/Jun/2025 12:16
Unit cell,
h k l, 0 0 0
Scan axis,Gonio
Scan range,10.009000000,40.000374400
Scan step size,0.0651986
No. of points, 460
Scan type,CONTINUOUS
Time per step,71.910
[Scan points]
Angle, TimePerStep, Intensity, ESD
10.041599320, 71.910, 5027.0, 70.9013
10.106797960, 71.910, 5033.0, 70.9436
10.171996600, 71.910, 4980.0, 70.5691
10.237195240, 71.910, 5035.0, 70.9577
10.302393880, 71.910, 5086.0, 71.3162
10.367592520, 71.910, 4984.0, 70.5975
10.432791160, 71.910, 4876.0, 69.8284
10.497989800, 71.910, 4851.0, 69.6491
10.563188440, 71.910, 5056.0, 71.1056
10.628387080, 71.910, 5054.0, 71.0915
10.693585720, 71.910, 4854.0, 69.6707
10.758784360, 71.910, 4942.0, 70.2994
10.823983000, 71.910, 4747.0, 68.8985
10.889181640, 71.910, 4949.0, 70.3491
10.954380280, 71.910, 4944.0, 70.3136
11.019578920, 71.910, 5064.0, 71.1618
11.084777560, 71.910, 4938.0, 70.2709
11.149976200, 71.910, 4860.0, 69.7137
11.215174840, 71.910, 5128.0, 71.6101
11.280373480, 71.910, 5123.0, 71.5751
11.345572120, 71.910, 5111.0, 71.4913
11.410770760, 71.910, 5017.0, 70.8308
11.475969400, 71.910, 5056.0, 71.1056
11.541168040, 71.910, 5016.0, 70.8237
11.606366680, 71.910, 4928.0, 70.1997
11.671565320, 71.910, 4991.0, 70.6470
11.736763960, 71.910, 5123.0, 71.5751
11.801962600, 71.910, 5089.0, 71.3372
11.867161240, 71.910, 5091.0, 71.3512
11.932359880, 71.910, 5021.0, 70.8590
11.997558520, 71.910, 5078.0, 71.2601
12.062757160, 71.910, 5220.0, 72.2496
12.127955800, 71.910, 5227.0, 72.2980
12.193154440, 71.910, 5234.0, 72.3464
12.258353080, 71.910, 5187.0, 72.0208
12.323551720, 71.910, 5259.0, 72.5190
12.388750360, 71.910, 5315.0, 72.9040
12.453949000, 71.910, 5162.0, 71.8471
12.519147640, 71.910, 5377.0, 73.3280
12.584346280, 71.910, 5280.0, 72.6636
12.649544920, 71.910, 5468.0, 73.9459
12.714743560, 71.910, 5365.0, 73.2462
12.779942200, 71.910, 5395.0, 73.4507
12.845140840, 71.910, 5352.0, 73.1574
12.910339480, 71.910, 5366.0, 73.2530
12.975538120, 71.910, 5569.0, 74.6257
13.040736760, 71.910, 5541.0, 74.4379
13.105935400, 71.910, 5475.0, 73.9932
13.171134040, 71.910, 5571.0, 74.6391
13.236332680, 71.910, 5667.0, 75.2795
13.301531320, 71.910, 5806.0, 76.1971
13.366729960, 71.910, 5651.0, 75.1731
13.431928600, 71.910, 5811.0, 76.2299
13.497127240, 71.910, 5971.0, 77.2722
13.562325880, 71.910, 5847.0, 76.4657
13.627524520, 71.910, 6018.0, 77.5758
13.692723160, 71.910, 6085.0, 78.0064
13.757921800, 71.910, 6000.0, 77.4597
13.823120440, 71.910, 6009.0, 77.5177
13.888319080, 71.910, 6173.0, 78.5684
13.953517720, 71.910, 6259.0, 79.1138
14.018716360, 71.910, 6373.0, 79.8311
14.083915000, 71.910, 6262.0, 79.1328
14.149113640, 71.910, 6430.0, 80.1873
14.214312280, 71.910, 6536.0, 80.8455
14.279510920, 71.910, 6580.0, 81.1172
14.344709560, 71.910, 6686.0, 81.7680
14.409908200, 71.910, 6666.0, 81.6456
14.475106840, 71.910, 6733.0, 82.0549
14.540305480, 71.910, 6869.0, 82.8794
14.605504120, 71.910, 6715.0, 81.9451
14.670702760, 71.910, 7080.0, 84.1427
14.735901400, 71.910, 6931.0, 83.2526
14.801100040, 71.910, 7069.0, 84.0773
14.866298680, 71.910, 7293.0, 85.3991
14.931497320, 71.910, 7358.0, 85.7788
14.996695960, 71.910, 7513.0, 86.6776
15.061894600, 71.910, 7602.0, 87.1894
15.127093240, 71.910, 7387.0, 85.9477
15.192291880, 71.910, 7742.0, 87.9886
15.257490520, 71.910, 7704.0, 87.7724
15.322689160, 71.910, 7721.0, 87.8692
15.387887800, 71.910, 7928.0, 89.0393
15.453086440, 71.910, 7886.0, 88.8032
15.518285080, 71.910, 7993.0, 89.4036
15.583483720, 71.910, 8131.0, 90.1721
15.648682360, 71.910, 8418.0, 91.7497
15.713881000, 71.910, 8488.0, 92.1303
15.779079640, 71.910, 8535.0, 92.3851
15.844278280, 71.910, 8673.0, 93.1289
15.909476920, 71.910, 8615.0, 92.8170
15.974675560, 71.910, 8850.0, 94.0744
16.039874200, 71.910, 8839.0, 94.0160
16.105072840, 71.910, 8988.0, 94.8051
16.170271480, 71.910, 9305.0, 96.4624
16.235470120, 71.910, 9218.0, 96.0104
16.300668760, 71.910, 9343.0, 96.6592
16.365867400, 71.910, 9402.0, 96.9639
16.431066040, 71.910, 9528.0, 97.6115
16.496264680, 71.910, 9841.0, 99.2018
16.561463320, 71.910, 9824.0, 99.1161
16.626661960, 71.910, 10010.0, 100.0500
16.691860600, 71.910, 10105.0, 100.5236
16.757059240, 71.910, 10303.0, 101.5037
16.822257880, 71.910, 10354.0, 101.7546
16.887456520, 71.910, 10302.0, 101.4988
16.952655160, 71.910, 10693.0, 103.4070
17.017853800, 71.910, 10866.0, 104.2401
17.083052440, 71.910, 10816.0, 104.0000
17.148251080, 71.910, 10821.0, 104.0240
17.213449720, 71.910, 11429.0, 106.9065
17.278648360, 71.910, 11449.0, 107.0000
17.343847000, 71.910, 11636.0, 107.8703
17.409045640, 71.910, 11915.0, 109.1559
17.474244280, 71.910, 12121.0, 110.0954
17.539442920, 71.910, 12550.0, 112.0268
17.604641560, 71.910, 12890.0, 113.5341
17.669840200, 71.910, 13418.0, 115.8361
17.735038840, 71.910, 13852.0, 117.6945
17.800237480, 71.910, 14588.0, 120.7808
17.865436120, 71.910, 15447.0, 124.2860
17.930634760, 71.910, 15945.0, 126.2735
17.995833400, 71.910, 16718.0, 129.2981
18.061032040, 71.910, 16743.0, 129.3947
18.126230680, 71.910, 17173.0, 131.0458
18.191429320, 71.910, 17120.0, 130.8434
18.256627960, 71.910, 17524.0, 132.3782
18.321826600, 71.910, 17165.0, 131.0153
18.387025240, 71.910, 17084.0, 130.7058
18.452223880, 71.910, 16892.0, 129.9692
18.517422520, 71.910, 16427.0, 128.1679
18.582621160, 71.910, 16050.0, 126.6886
18.647819800, 71.910, 15623.0, 124.9920
18.713018440, 71.910, 15419.0, 124.1733
18.778217080, 71.910, 14978.0, 122.3846
18.843415720, 71.910, 14314.0, 119.6411
18.908614360, 71.910, 14083.0, 118.6718
18.973813000, 71.910, 13925.0, 118.0042
19.039011640, 71.910, 13562.0, 116.4560
19.104210280, 71.910, 13349.0, 115.5379
19.169408920, 71.910, 13238.0, 115.0565
19.234607560, 71.910, 13034.0, 114.1665
19.299806200, 71.910, 12753.0, 112.9292
19.365004840, 71.910, 12821.0, 113.2299
19.430203480, 71.910, 12671.0, 112.5655
19.495402120, 71.910, 12823.0, 113.2387
19.560600760, 71.910, 12662.0, 112.5256
19.625799400, 71.910, 12574.0, 112.1338
19.690998040, 71.910, 12886.0, 113.5165
19.756196680, 71.910, 12628.0, 112.3744
19.821395320, 71.910, 12726.0, 112.8096
19.886593960, 71.910, 12997.0, 114.0044
19.951792600, 71.910, 12937.0, 113.7409
20.016991240, 71.910, 13097.0, 114.4421
20.082189880, 71.910, 13149.0, 114.6691
20.147388520, 71.910, 13067.0, 114.3110
20.212587160, 71.910, 13006.0, 114.0439
20.277785800, 71.910, 13079.0, 114.3635
20.342984440, 71.910, 12815.0, 113.2034
20.408183080, 71.910, 12722.0, 112.7918
20.473381720, 71.910, 12417.0, 111.4316
20.538580360, 71.910, 12600.0, 112.2497
20.603779000, 71.910, 12420.0, 111.4451
20.668977640, 71.910, 12141.0, 110.1862
20.734176280, 71.910, 11963.0, 109.3755
20.799374920, 71.910, 12005.0, 109.5673
20.864573560, 71.910, 11907.0, 109.1192
20.929772200, 71.910, 11868.0, 108.9404
20.994970840, 71.910, 11768.0, 108.4804
21.060169480, 71.910, 11622.0, 107.8054
21.125368120, 71.910, 11748.0, 108.3882
21.190566760, 71.910, 11836.0, 108.7934
21.255765400, 71.910, 11822.0, 108.7290
21.320964040, 71.910, 11897.0, 109.0734
21.386162680, 71.910, 11714.0, 108.2312
21.451361320, 71.910, 12033.0, 109.6950
21.516559960, 71.910, 12210.0, 110.4989
21.581758600, 71.910, 12109.0, 110.0409
21.646957240, 71.910, 12008.0, 109.5810
21.712155880, 71.910, 12232.0, 110.5984
21.777354520, 71.910, 12203.0, 110.4672
21.842553160, 71.910, 12120.0, 110.0909
21.907751800, 71.910, 11893.0, 109.0550
21.972950440, 71.910, 11973.0, 109.4212
22.038149080, 71.910, 11655.0, 107.9583
22.103347720, 71.910, 11702.0, 108.1758
22.168546360, 71.910, 11302.0, 106.3109
22.233745000, 71.910, 11157.0, 105.6267
22.298943640, 71.910, 11043.0, 105.0857
22.364142280, 71.910, 10971.0, 104.7425
22.429340920, 71.910, 10498.0, 102.4597
22.494539560, 71.910, 10273.0, 101.3558
22.559738200, 71.910, 10161.0, 100.8018
22.624936840, 71.910, 9903.0, 99.5138
22.690135480, 71.910, 9826.0, 99.1262
22.755334120, 71.910, 9621.0, 98.0867
22.820532760, 71.910, 9495.0, 97.4423
22.885731400, 71.910, 9320.0, 96.5401
22.950930040, 71.910, 9074.0, 95.2575
23.016128680, 71.910, 8930.0, 94.4987
23.081327320, 71.910, 8730.0, 93.4345
23.146525960, 71.910, 8682.0, 93.1773
23.211724600, 71.910, 8582.0, 92.6391
23.276923240, 71.910, 8675.0, 93.1397
23.342121880, 71.910, 8482.0, 92.0978
23.407320520, 71.910, 8117.0, 90.0944
23.472519160, 71.910, 8293.0, 91.0659
23.537717800, 71.910, 8042.0, 89.6772
23.602916440, 71.910, 8052.0, 89.7329
23.668115080, 71.910, 7893.0, 88.8426
23.733313720, 71.910, 7958.0, 89.2076
23.798512360, 71.910, 7974.0, 89.2973
23.863711000, 71.910, 7810.0, 88.3742
23.928909640, 71.910, 7683.0, 87.6527
23.994108280, 71.910, 7810.0, 88.3742
24.059306920, 71.910, 7730.0, 87.9204
24.124505560, 71.910, 7673.0, 87.5957
24.189704200, 71.910, 7716.0, 87.8408
24.254902840, 71.910, 7528.0, 86.7640
24.320101480, 71.910, 7474.0, 86.4523
24.385300120, 71.910, 7669.0, 87.5728
24.450498760, 71.910, 7529.0, 86.7698
24.515697400, 71.910, 7404.0, 86.0465
24.580896040, 71.910, 7383.0, 85.9244
24.646094680, 71.910, 7387.0, 85.9477
24.711293320, 71.910, 7485.0, 86.5159
24.776491960, 71.910, 7550.0, 86.8907
24.841690600, 71.910, 7414.0, 86.1046
24.906889240, 71.910, 7357.0, 85.7730
24.972087880, 71.910, 7326.0, 85.5921
25.037286520, 71.910, 7348.0, 85.7205
25.102485160, 71.910, 7285.0, 85.3522
25.167683800, 71.910, 7483.0, 86.5043
25.232882440, 71.910, 7463.0, 86.3887
25.298081080, 71.910, 7238.0, 85.0764
25.363279720, 71.910, 7314.0, 85.5219
25.428478360, 71.910, 7301.0, 85.4459
25.493677000, 71.910, 7395.0, 85.9942
25.558875640, 71.910, 7301.0, 85.4459
25.624074280, 71.910, 7183.0, 84.7526
25.689272920, 71.910, 7191.0, 84.7998
25.754471560, 71.910, 7180.0, 84.7349
25.819670200, 71.910, 7372.0, 85.8604
25.884868840, 71.910, 7232.0, 85.0412
25.950067480, 71.910, 7196.0, 84.8292
26.015266120, 71.910, 7396.0, 86.0000
26.080464760, 71.910, 7261.0, 85.2115
26.145663400, 71.910, 7273.0, 85.2819
26.210862040, 71.910, 7136.0, 84.4748
26.276060680, 71.910, 7197.0, 84.8351
26.341259320, 71.910, 7015.0, 83.7556
26.406457960, 71.910, 7065.0, 84.0536
26.471656600, 71.910, 7202.0, 84.8646
26.536855240, 71.910, 6963.0, 83.4446
26.602053880, 71.910, 7357.0, 85.7730
26.667252520, 71.910, 7104.0, 84.2852
26.732451160, 71.910, 7165.0, 84.6463
26.797649800, 71.910, 7267.0, 85.2467
26.862848440, 71.910, 7165.0, 84.6463
26.928047080, 71.910, 7304.0, 85.4634
26.993245720, 71.910, 7340.0, 85.6738
27.058444360, 71.910, 7349.0, 85.7263
27.123643000, 71.910, 7429.0, 86.1916
27.188841640, 71.910, 7574.0, 87.0287
27.254040280, 71.910, 7419.0, 86.1336
27.319238920, 71.910, 7488.0, 86.5332
27.384437560, 71.910, 7759.0, 88.0852
27.449636200, 71.910, 7690.0, 87.6926
27.514834840, 71.910, 7966.0, 89.2525
27.580033480, 71.910, 7985.0, 89.3588
27.645232120, 71.910, 8082.0, 89.8999
27.710430760, 71.910, 8215.0, 90.6366
27.775629400, 71.910, 8323.0, 91.2305
27.840828040, 71.910, 8367.0, 91.4713
27.906026680, 71.910, 8241.0, 90.7800
27.971225320, 71.910, 8275.0, 90.9670
28.036423960, 71.910, 8258.0, 90.8735
28.101622600, 71.910, 8316.0, 91.1921
28.166821240, 71.910, 8204.0, 90.5759
28.232019880, 71.910, 8032.0, 89.6214
28.297218520, 71.910, 7973.0, 89.2917
28.362417160, 71.910, 7965.0, 89.2468
28.427615800, 71.910, 7786.0, 88.2383
28.492814440, 71.910, 7946.0, 89.1403
28.558013080, 71.910, 7808.0, 88.3629
28.623211720, 71.910, 7735.0, 87.9488
28.688410360, 71.910, 7485.0, 86.5159
28.753609000, 71.910, 7752.0, 88.0454
28.818807640, 71.910, 7600.0, 87.1780
28.884006280, 71.910, 7680.0, 87.6356
28.949204920, 71.910, 7550.0, 86.8907
29.014403560, 71.910, 7454.0, 86.3366
29.079602200, 71.910, 7456.0, 86.3481
29.144800840, 71.910, 7535.0, 86.8044
29.209999480, 71.910, 7601.0, 87.1837
29.275198120, 71.910, 7455.0, 86.3423
29.340396760, 71.910, 7448.0, 86.3018
29.405595400, 71.910, 7309.0, 85.4927
29.470794040, 71.910, 7412.0, 86.0930
29.535992680, 71.910, 7253.0, 85.1645
29.601191320, 71.910, 7251.0, 85.1528
29.666389960, 71.910, 7213.0, 84.9294
29.731588600, 71.910, 7326.0, 85.5921
29.796787240, 71.910, 7392.0, 85.9767
29.861985880, 71.910, 7198.0, 84.8410
29.927184520, 71.910, 7407.0, 86.0639
29.992383160, 71.910, 7235.0, 85.0588
30.057581800, 71.910, 7296.0, 85.4166
30.122780440, 71.910, 7088.0, 84.1903
30.187979080, 71.910, 7188.0, 84.7821
30.253177720, 71.910, 7085.0, 84.1724
30.318376360, 71.910, 7014.0, 83.7496
30.383575000, 71.910, 7223.0, 84.9882
30.448773640, 71.910, 7207.0, 84.8941
30.513972280, 71.910, 7093.0, 84.2200
30.579170920, 71.910, 7303.0, 85.4576
30.644369560, 71.910, 7189.0, 84.7880
30.709568200, 71.910, 7176.0, 84.7113
30.774766840, 71.910, 7318.0, 85.5453
30.839965480, 71.910, 7077.0, 84.1249
30.905164120, 71.910, 7151.0, 84.5636
30.970362760, 71.910, 7358.0, 85.7788
31.035561400, 71.910, 7188.0, 84.7821
31.100760040, 71.910, 7063.0, 84.0417
31.165958680, 71.910, 7237.0, 85.0706
31.231157320, 71.910, 7220.0, 84.9706
31.296355960, 71.910, 7176.0, 84.7113
31.361554600, 71.910, 7381.0, 85.9127
31.426753240, 71.910, 7333.0, 85.6329
31.491951880, 71.910, 7147.0, 84.5399
31.557150520, 71.910, 7186.0, 84.7703
31.622349160, 71.910, 7272.0, 85.2760
31.687547800, 71.910, 7370.0, 85.8487
31.752746440, 71.910, 7469.0, 86.4234
31.817945080, 71.910, 7483.0, 86.5043
31.883143720, 71.910, 7482.0, 86.4986
31.948342360, 71.910, 7500.0, 86.6025
32.013541000, 71.910, 7423.0, 86.1568
32.078739640, 71.910, 7526.0, 86.7525
32.143938280, 71.910, 7477.0, 86.4696
32.209136920, 71.910, 7311.0, 85.5044
32.274335560, 71.910, 7593.0, 87.1378
32.339534200, 71.910, 7479.0, 86.4812
32.404732840, 71.910, 7605.0, 87.2067
32.469931480, 71.910, 7545.0, 86.8620
32.535130120, 71.910, 7630.0, 87.3499
32.600328760, 71.910, 7596.0, 87.1550
32.665527400, 71.910, 7544.0, 86.8562
32.730726040, 71.910, 7294.0, 85.4049
32.795924680, 71.910, 7525.0, 86.7468
32.861123320, 71.910, 7460.0, 86.3713
32.926321960, 71.910, 7800.0, 88.3176
32.991520600, 71.910, 7401.0, 86.0291
33.056719240, 71.910, 7550.0, 86.8907
33.121917880, 71.910, 7505.0, 86.6314
33.187116520, 71.910, 7516.0, 86.6949
33.252315160, 71.910, 7409.0, 86.0755
33.317513800, 71.910, 7336.0, 85.6505
33.382712440, 71.910, 7465.0, 86.4002
33.447911080, 71.910, 7488.0, 86.5332
33.513109720, 71.910, 7449.0, 86.3076
33.578308360, 71.910, 7672.0, 87.5900
33.643507000, 71.910, 7489.0, 86.5390
33.708705640, 71.910, 7433.0, 86.2148
33.773904280, 71.910, 7397.0, 86.0058
33.839102920, 71.910, 7593.0, 87.1378
33.904301560, 71.910, 7378.0, 85.8953
33.969500200, 71.910, 7618.0, 87.2812
34.034698840, 71.910, 7518.0, 86.7064
34.099897480, 71.910, 7431.0, 86.2032
34.165096120, 71.910, 7482.0, 86.4986
34.230294760, 71.910, 7478.0, 86.4754
34.295493400, 71.910, 7596.0, 87.1550
34.360692040, 71.910, 7589.0, 87.1149
34.425890680, 71.910, 7433.0, 86.2148
34.491089320, 71.910, 7422.0, 86.1510
34.556287960, 71.910, 7478.0, 86.4754
34.621486600, 71.910, 7409.0, 86.0755
34.686685240, 71.910, 7364.0, 85.8138
34.751883880, 71.910, 7374.0, 85.8720
34.817082520, 71.910, 7389.0, 85.9593
34.882281160, 71.910, 7592.0, 87.1321
34.947479800, 71.910, 7391.0, 85.9709
35.012678440, 71.910, 7551.0, 86.8965
35.077877080, 71.910, 7437.0, 86.2380
35.143075720, 71.910, 7384.0, 85.9302
35.208274360, 71.910, 7543.0, 86.8504
35.273473000, 71.910, 7565.0, 86.9770
35.338671640, 71.910, 7501.0, 86.6083
35.403870280, 71.910, 7377.0, 85.8895
35.469068920, 71.910, 7325.0, 85.5862
35.534267560, 71.910, 7456.0, 86.3481
35.599466200, 71.910, 7429.0, 86.1916
35.664664840, 71.910, 7307.0, 85.4810
35.729863480, 71.910, 7458.0, 86.3597
35.795062120, 71.910, 7427.0, 86.1800
35.860260760, 71.910, 7506.0, 86.6372
35.925459400, 71.910, 7519.0, 86.7122
35.990658040, 71.910, 7529.0, 86.7698
36.055856680, 71.910, 7435.0, 86.2264
36.121055320, 71.910, 7308.0, 85.4868
36.186253960, 71.910, 7404.0, 86.0465
36.251452600, 71.910, 7434.0, 86.2206
36.316651240, 71.910, 7531.0, 86.7813
36.381849880, 71.910, 7427.0, 86.1800
36.447048520, 71.910, 7347.0, 85.7146
36.512247160, 71.910, 7422.0, 86.1510
36.577445800, 71.910, 7434.0, 86.2206
36.642644440, 71.910, 7433.0, 86.2148
36.707843080, 71.910, 7543.0, 86.8504
36.773041720, 71.910, 7589.0, 87.1149
36.838240360, 71.910, 7538.0, 86.8217
36.903439000, 71.910, 7472.0, 86.4407
36.968637640, 71.910, 7291.0, 85.3874
37.033836280, 71.910, 7589.0, 87.1149
37.099034920, 71.910, 7474.0, 86.4523
37.164233560, 71.910, 7430.0, 86.1974
37.229432200, 71.910, 7543.0, 86.8504
37.294630840, 71.910, 7718.0, 87.8521
37.359829480, 71.910, 7640.0, 87.4071
37.425028120, 71.910, 7473.0, 86.4465
37.490226760, 71.910, 7512.0, 86.6718
37.555425400, 71.910, 7439.0, 86.2496
37.620624040, 71.910, 7441.0, 86.2612
37.685822680, 71.910, 7400.0, 86.0233
37.751021320, 71.910, 7484.0, 86.5101
37.816219960, 71.910, 7641.0, 87.4128
37.881418600, 71.910, 7702.0, 87.7610
37.946617240, 71.910, 7622.0, 87.3041
38.011815880, 71.910, 7619.0, 87.2869
38.077014520, 71.910, 7416.0, 86.1162
38.142213160, 71.910, 7586.0, 87.0976
38.207411800, 71.910, 7669.0, 87.5728
38.272610440, 71.910, 7480.0, 86.4870
38.337809080, 71.910, 7622.0, 87.3041
38.403007720, 71.910, 7431.0, 86.2032
38.468206360, 71.910, 7560.0, 86.9483
38.533405000, 71.910, 7420.0, 86.1394
38.598603640, 71.910, 7336.0, 85.6505
38.663802280, 71.910, 7577.0, 87.0460
38.729000920, 71.910, 7436.0, 86.2322
38.794199560, 71.910, 7385.0, 85.9360
38.859398200, 71.910, 7423.0, 86.1568
38.924596840, 71.910, 7558.0, 86.9368
38.989795480, 71.910, 7480.0, 86.4870
39.054994120, 71.910, 7445.0, 86.2844
39.120192760, 71.910, 7508.0, 86.6487
39.185391400, 71.910, 7458.0, 86.3597
39.250590040, 71.910, 7535.0, 86.8044
39.315788680, 71.910, 7361.0, 85.7963
39.380987320, 71.910, 7475.0, 86.4581
39.446185960, 71.910, 7463.0, 86.3887
39.511384600, 71.910, 7529.0, 86.7698
39.576583240, 71.910, 7387.0, 85.9477
39.641781880, 71.910, 7389.0, 85.9593
39.706980520, 71.910, 7488.0, 86.5332
39.772179160, 71.910, 7318.0, 85.5453
39.837377800, 71.910, 7546.0, 86.8677
39.902576440, 71.910, 7385.0, 85.9360
39.967775080, 71.910, 7522.0, 86.7295